Workbook

Sheet Panel
A1: CENTRO DE OPERACIONES / TIENDA ONLINE
A3: SIMULACIÓN · Fecha de corte: 21 OCT 2026 · Moneda: CLP · Actualiza informes con Python
A5: PEDIDOS | D5: VENTAS NOMINALES | G5: INCIDENCIAS ABIERTAS | J5: INCIDENCIAS RESUELTAS | M5: ENVÍOS ENTREGADOS
A6: =COUNTA(Pedidos!$A$2:$A$501) -> 500 | D6: =SUM(Pedidos!$G$2:$G$501) -> 12057790 | G6: =COUNTIF(Incidencias!$G$2:$G$126,"ABIERTO") -> 125 | J6: =COUNTIF(Incidencias!$G$2:$G$126,"RESUELTO") -> 0 | M6: =COUNTIF(Envios!$E$2:$E$501,"ENTREGADO") -> 414
A10: CONTROLES DE CALIDAD OPERATIVA
A11: DUPLICADOS | D11: PAGOS DISTINTOS | G11: ENVÍOS ATRASADOS | J11: SLA INCUMPLIDOS | M11: PAGOS PENDIENTES
A12: =COUNTIF(Incidencias!$B$2:$B$126,"POSIBLE_DUPLICADO") -> 14 | D12: =COUNTIF(Incidencias!$B$2:$B$126,"PAGO_DIFERENTE") -> 16 | G12: =COUNTIF(Incidencias!$B$2:$B$126,"ENVIO_ATRASADO") -> 52 | J12: =COUNTIF(Incidencias!$B$2:$B$126,"SLA_INCUMPLIDO") -> 43 | M12: =COUNTIF(Pagos!$D$2:$D$501,"PENDIENTE") -> 10
A15: PEDIDOS POR REGIÓN | H15: INCIDENCIAS POR CATEGORÍA
A16: Región | B16: Pedidos | C16: Ventas CLP | D16: Participación | H16: Tipo | I16: Detectadas | J16: Abiertas | K16: Resueltas | R16: REGION (GRÁFICO) | S16: PEDIDOS
A17: Biobío | B17: =COUNTIF(Pedidos!$H$2:$H$501,A17) -> 91 | C17: =SUMIF(Pedidos!$H$2:$H$501,A17,Pedidos!$G$2:$G$501) -> 2019960 | D17: =B17/$A$6 -> 0.182 | H17: Duplicados | I17: =COUNTIF(Incidencias!$B$2:$B$126,"POSIBLE_DUPLICADO") -> 14 | J17: =COUNTIFS(Incidencias!$B$2:$B$126,"POSIBLE_DUPLICADO",Incidencias!$G$2:$G$126,"ABIERTO") -> 14 | K17: =COUNTIFS(Incidencias!$B$2:$B$126,"POSIBLE_DUPLICADO",Incidencias!$G$2:$G$126,"RESUELTO") -> 0 | R17: =A17 -> Biobío | S17: =B17 -> 91
A18: Coquimbo | B18: =COUNTIF(Pedidos!$H$2:$H$501,A18) -> 80 | C18: =SUMIF(Pedidos!$H$2:$H$501,A18,Pedidos!$G$2:$G$501) -> 1975010 | D18: =B18/$A$6 -> 0.16 | H18: Pagos | I18: =COUNTIF(Incidencias!$B$2:$B$126,"PAGO_DIFERENTE") -> 16 | J18: =COUNTIFS(Incidencias!$B$2:$B$126,"PAGO_DIFERENTE",Incidencias!$G$2:$G$126,"ABIERTO") -> 16 | K18: =COUNTIFS(Incidencias!$B$2:$B$126,"PAGO_DIFERENTE",Incidencias!$G$2:$G$126,"RESUELTO") -> 0 | R18: =A18 -> Coquimbo | S18: =B18 -> 80
A19: Los Lagos | B19: =COUNTIF(Pedidos!$H$2:$H$501,A19) -> 85 | C19: =SUMIF(Pedidos!$H$2:$H$501,A19,Pedidos!$G$2:$G$501) -> 2055930 | D19: =B19/$A$6 -> 0.17 | H19: Envíos | I19: =COUNTIF(Incidencias!$B$2:$B$126,"ENVIO_ATRASADO") -> 52 | J19: =COUNTIFS(Incidencias!$B$2:$B$126,"ENVIO_ATRASADO",Incidencias!$G$2:$G$126,"ABIERTO") -> 52 | K19: =COUNTIFS(Incidencias!$B$2:$B$126,"ENVIO_ATRASADO",Incidencias!$G$2:$G$126,"RESUELTO") -> 0 | R19: =A19 -> Los Lagos | S19: =B19 -> 85
A20: Maule | B20: =COUNTIF(Pedidos!$H$2:$H$501,A20) -> 80 | C20: =SUMIF(Pedidos!$H$2:$H$501,A20,Pedidos!$G$2:$G$501) -> 1914030 | D20: =B20/$A$6 -> 0.16 | H20: SLA | I20: =COUNTIF(Incidencias!$B$2:$B$126,"SLA_INCUMPLIDO") -> 43 | J20: =COUNTIFS(Incidencias!$B$2:$B$126,"SLA_INCUMPLIDO",Incidencias!$G$2:$G$126,"ABIERTO") -> 43 | K20: =COUNTIFS(Incidencias!$B$2:$B$126,"SLA_INCUMPLIDO",Incidencias!$G$2:$G$126,"RESUELTO") -> 0 | R20: =A20 -> Maule | S20: =B20 -> 80
A21: Metropolitana | B21: =COUNTIF(Pedidos!$H$2:$H$501,A21) -> 85 | C21: =SUMIF(Pedidos!$H$2:$H$501,A21,Pedidos!$G$2:$G$501) -> 2071940 | D21: =B21/$A$6 -> 0.17 | R21: =A21 -> Metropolitana | S21: =B21 -> 85
A22: Valparaíso | B22: =COUNTIF(Pedidos!$H$2:$H$501,A22) -> 79 | C22: =SUMIF(Pedidos!$H$2:$H$501,A22,Pedidos!$G$2:$G$501) -> 2020920 | D22: =B22/$A$6 -> 0.158 | R22: =A22 -> Valparaíso | S22: =B22 -> 79
A23: GRÁFICOS DE SEGUIMIENTO | S23: 0
A41: Todos los registros son ficticios. El dashboard refleja el CSV del corte; resoluciones nuevas requieren importar Incidencias de nuevo.

Sheet Resumen_cruzado
A1: RESUMEN CRUZADO · REGIÓN Y CATEGORÍA
A3: Matriz dinámica por fórmulas (no objeto PivotTable). Para tabla dinámica nativa, consulta docs/publicar.md.
A5: PEDIDOS / REGIÓN | B5: ACC | C5: DEP | D5: HOG | E5: MOD | F5: OFI | G5: TEC | H5: TOTAL
A6: Biobío | B6: =COUNTIFS(Pedidos!$H$2:$H$501,$A6,Pedidos!$E$2:$E$501,B$5) -> 13 | C6: =COUNTIFS(Pedidos!$H$2:$H$501,$A6,Pedidos!$E$2:$E$501,C$5) -> 14 | D6: =COUNTIFS(Pedidos!$H$2:$H$501,$A6,Pedidos!$E$2:$E$501,D$5) -> 13 | E6: =COUNTIFS(Pedidos!$H$2:$H$501,$A6,Pedidos!$E$2:$E$501,E$5) -> 17 | F6: =COUNTIFS(Pedidos!$H$2:$H$501,$A6,Pedidos!$E$2:$E$501,F$5) -> 15 | G6: =COUNTIFS(Pedidos!$H$2:$H$501,$A6,Pedidos!$E$2:$E$501,G$5) -> 19 | H6: =SUM(B6:G6) -> 91
A7: Coquimbo | B7: =COUNTIFS(Pedidos!$H$2:$H$501,$A7,Pedidos!$E$2:$E$501,B$5) -> 18 | C7: =COUNTIFS(Pedidos!$H$2:$H$501,$A7,Pedidos!$E$2:$E$501,C$5) -> 14 | D7: =COUNTIFS(Pedidos!$H$2:$H$501,$A7,Pedidos!$E$2:$E$501,D$5) -> 18 | E7: =COUNTIFS(Pedidos!$H$2:$H$501,$A7,Pedidos!$E$2:$E$501,E$5) -> 10 | F7: =COUNTIFS(Pedidos!$H$2:$H$501,$A7,Pedidos!$E$2:$E$501,F$5) -> 8 | G7: =COUNTIFS(Pedidos!$H$2:$H$501,$A7,Pedidos!$E$2:$E$501,G$5) -> 12 | H7: =SUM(B7:G7) -> 80
A8: Los Lagos | B8: =COUNTIFS(Pedidos!$H$2:$H$501,$A8,Pedidos!$E$2:$E$501,B$5) -> 13 | C8: =COUNTIFS(Pedidos!$H$2:$H$501,$A8,Pedidos!$E$2:$E$501,C$5) -> 11 | D8: =COUNTIFS(Pedidos!$H$2:$H$501,$A8,Pedidos!$E$2:$E$501,D$5) -> 14 | E8: =COUNTIFS(Pedidos!$H$2:$H$501,$A8,Pedidos!$E$2:$E$501,E$5) -> 19 | F8: =COUNTIFS(Pedidos!$H$2:$H$501,$A8,Pedidos!$E$2:$E$501,F$5) -> 9 | G8: =COUNTIFS(Pedidos!$H$2:$H$501,$A8,Pedidos!$E$2:$E$501,G$5) -> 19 | H8: =SUM(B8:G8) -> 85
A9: Maule | B9: =COUNTIFS(Pedidos!$H$2:$H$501,$A9,Pedidos!$E$2:$E$501,B$5) -> 18 | C9: =COUNTIFS(Pedidos!$H$2:$H$501,$A9,Pedidos!$E$2:$E$501,C$5) -> 18 | D9: =COUNTIFS(Pedidos!$H$2:$H$501,$A9,Pedidos!$E$2:$E$501,D$5) -> 8 | E9: =COUNTIFS(Pedidos!$H$2:$H$501,$A9,Pedidos!$E$2:$E$501,E$5) -> 7 | F9: =COUNTIFS(Pedidos!$H$2:$H$501,$A9,Pedidos!$E$2:$E$501,F$5) -> 15 | G9: =COUNTIFS(Pedidos!$H$2:$H$501,$A9,Pedidos!$E$2:$E$501,G$5) -> 14 | H9: =SUM(B9:G9) -> 80
A10: Metropolitana | B10: =COUNTIFS(Pedidos!$H$2:$H$501,$A10,Pedidos!$E$2:$E$501,B$5) -> 14 | C10: =COUNTIFS(Pedidos!$H$2:$H$501,$A10,Pedidos!$E$2:$E$501,C$5) -> 17 | D10: =COUNTIFS(Pedidos!$H$2:$H$501,$A10,Pedidos!$E$2:$E$501,D$5) -> 15 | E10: =COUNTIFS(Pedidos!$H$2:$H$501,$A10,Pedidos!$E$2:$E$501,E$5) -> 12 | F10: =COUNTIFS(Pedidos!$H$2:$H$501,$A10,Pedidos!$E$2:$E$501,F$5) -> 17 | G10: =COUNTIFS(Pedidos!$H$2:$H$501,$A10,Pedidos!$E$2:$E$501,G$5) -> 10 | H10: =SUM(B10:G10) -> 85
A11: Valparaíso | B11: =COUNTIFS(Pedidos!$H$2:$H$501,$A11,Pedidos!$E$2:$E$501,B$5) -> 18 | C11: =COUNTIFS(Pedidos!$H$2:$H$501,$A11,Pedidos!$E$2:$E$501,C$5) -> 13 | D11: =COUNTIFS(Pedidos!$H$2:$H$501,$A11,Pedidos!$E$2:$E$501,D$5) -> 10 | E11: =COUNTIFS(Pedidos!$H$2:$H$501,$A11,Pedidos!$E$2:$E$501,E$5) -> 8 | F11: =COUNTIFS(Pedidos!$H$2:$H$501,$A11,Pedidos!$E$2:$E$501,F$5) -> 14 | G11: =COUNTIFS(Pedidos!$H$2:$H$501,$A11,Pedidos!$E$2:$E$501,G$5) -> 16 | H11: =SUM(B11:G11) -> 79
A12: TOTAL | B12: =SUM(B6:B11) -> 94 | C12: =SUM(C6:C11) -> 87 | D12: =SUM(D6:D11) -> 78 | E12: =SUM(E6:E11) -> 73 | F12: =SUM(F6:F11) -> 78 | G12: =SUM(G6:G11) -> 90 | H12: =SUM(H6:H11) -> 500
A15: VENTAS NOMINALES (CLP) / REGIÓN | B15: ACC | C15: DEP | D15: HOG | E15: MOD | F15: OFI | G15: TEC | H15: TOTAL
A16: Biobío | B16: =SUMIFS(Pedidos!$G$2:$G$501,Pedidos!$H$2:$H$501,$A16,Pedidos!$E$2:$E$501,B$15) -> 134850 | C16: =SUMIFS(Pedidos!$G$2:$G$501,Pedidos!$H$2:$H$501,$A16,Pedidos!$E$2:$E$501,C$15) -> 559840 | D16: =SUMIFS(Pedidos!$G$2:$G$501,Pedidos!$H$2:$H$501,$A16,Pedidos!$E$2:$E$501,D$15) -> 374850 | E16: =SUMIFS(Pedidos!$G$2:$G$501,Pedidos!$H$2:$H$501,$A16,Pedidos!$E$2:$E$501,E$15) -> 303810 | F16: =SUMIFS(Pedidos!$G$2:$G$501,Pedidos!$H$2:$H$501,$A16,Pedidos!$E$2:$E$501,F$15) -> 246810 | G16: =SUMIFS(Pedidos!$G$2:$G$501,Pedidos!$H$2:$H$501,$A16,Pedidos!$E$2:$E$501,G$15) -> 399800 | H16: =SUM(B16:G16) -> 2019960
A17: Coquimbo | B17: =SUMIFS(Pedidos!$G$2:$G$501,Pedidos!$H$2:$H$501,$A17,Pedidos!$E$2:$E$501,B$15) -> 170810 | C17: =SUMIFS(Pedidos!$G$2:$G$501,Pedidos!$H$2:$H$501,$A17,Pedidos!$E$2:$E$501,C$15) -> 559840 | D17: =SUMIFS(Pedidos!$G$2:$G$501,Pedidos!$H$2:$H$501,$A17,Pedidos!$E$2:$E$501,D$15) -> 574770 | E17: =SUMIFS(Pedidos!$G$2:$G$501,Pedidos!$H$2:$H$501,$A17,Pedidos!$E$2:$E$501,E$15) -> 207870 | F17: =SUMIFS(Pedidos!$G$2:$G$501,Pedidos!$H$2:$H$501,$A17,Pedidos!$E$2:$E$501,F$15) -> 181860 | G17: =SUMIFS(Pedidos!$G$2:$G$501,Pedidos!$H$2:$H$501,$A17,Pedidos!$E$2:$E$501,G$15) -> 279860 | H17: =SUM(B17:G17) -> 1975010
A18: Los Lagos | B18: =SUMIFS(Pedidos!$G$2:$G$501,Pedidos!$H$2:$H$501,$A18,Pedidos!$E$2:$E$501,B$15) -> 161820 | C18: =SUMIFS(Pedidos!$G$2:$G$501,Pedidos!$H$2:$H$501,$A18,Pedidos!$E$2:$E$501,C$15) -> 419880 | D18: =SUMIFS(Pedidos!$G$2:$G$501,Pedidos!$H$2:$H$501,$A18,Pedidos!$E$2:$E$501,D$15) -> 449820 | E18: =SUMIFS(Pedidos!$G$2:$G$501,Pedidos!$H$2:$H$501,$A18,Pedidos!$E$2:$E$501,E$15) -> 367770 | F18: =SUMIFS(Pedidos!$G$2:$G$501,Pedidos!$H$2:$H$501,$A18,Pedidos!$E$2:$E$501,F$15) -> 116910 | G18: =SUMIFS(Pedidos!$G$2:$G$501,Pedidos!$H$2:$H$501,$A18,Pedidos!$E$2:$E$501,G$15) -> 539730 | H18: =SUM(B18:G18) -> 2055930
A19: Maule | B19: =SUMIFS(Pedidos!$G$2:$G$501,Pedidos!$H$2:$H$501,$A19,Pedidos!$E$2:$E$501,B$15) -> 197780 | C19: =SUMIFS(Pedidos!$G$2:$G$501,Pedidos!$H$2:$H$501,$A19,Pedidos!$E$2:$E$501,C$15) -> 734790 | D19: =SUMIFS(Pedidos!$G$2:$G$501,Pedidos!$H$2:$H$501,$A19,Pedidos!$E$2:$E$501,D$15) -> 249900 | E19: =SUMIFS(Pedidos!$G$2:$G$501,Pedidos!$H$2:$H$501,$A19,Pedidos!$E$2:$E$501,E$15) -> 143910 | F19: =SUMIFS(Pedidos!$G$2:$G$501,Pedidos!$H$2:$H$501,$A19,Pedidos!$E$2:$E$501,F$15) -> 207840 | G19: =SUMIFS(Pedidos!$G$2:$G$501,Pedidos!$H$2:$H$501,$A19,Pedidos!$E$2:$E$501,G$15) -> 379810 | H19: =SUM(B19:G19) -> 1914030
A20: Metropolitana | B20: =SUMIFS(Pedidos!$G$2:$G$501,Pedidos!$H$2:$H$501,$A20,Pedidos!$E$2:$E$501,B$15) -> 161820 | C20: =SUMIFS(Pedidos!$G$2:$G$501,Pedidos!$H$2:$H$501,$A20,Pedidos!$E$2:$E$501,C$15) -> 629820 | D20: =SUMIFS(Pedidos!$G$2:$G$501,Pedidos!$H$2:$H$501,$A20,Pedidos!$E$2:$E$501,D$15) -> 474810 | E20: =SUMIFS(Pedidos!$G$2:$G$501,Pedidos!$H$2:$H$501,$A20,Pedidos!$E$2:$E$501,E$15) -> 239850 | F20: =SUMIFS(Pedidos!$G$2:$G$501,Pedidos!$H$2:$H$501,$A20,Pedidos!$E$2:$E$501,F$15) -> 285780 | G20: =SUMIFS(Pedidos!$G$2:$G$501,Pedidos!$H$2:$H$501,$A20,Pedidos!$E$2:$E$501,G$15) -> 279860 | H20: =SUM(B20:G20) -> 2071940
A21: Valparaíso | B21: =SUMIFS(Pedidos!$G$2:$G$501,Pedidos!$H$2:$H$501,$A21,Pedidos!$E$2:$E$501,B$15) -> 224750 | C21: =SUMIFS(Pedidos!$G$2:$G$501,Pedidos!$H$2:$H$501,$A21,Pedidos!$E$2:$E$501,C$15) -> 559840 | D21: =SUMIFS(Pedidos!$G$2:$G$501,Pedidos!$H$2:$H$501,$A21,Pedidos!$E$2:$E$501,D$15) -> 374850 | E21: =SUMIFS(Pedidos!$G$2:$G$501,Pedidos!$H$2:$H$501,$A21,Pedidos!$E$2:$E$501,E$15) -> 207870 | F21: =SUMIFS(Pedidos!$G$2:$G$501,Pedidos!$H$2:$H$501,$A21,Pedidos!$E$2:$E$501,F$15) -> 233820 | G21: =SUMIFS(Pedidos!$G$2:$G$501,Pedidos!$H$2:$H$501,$A21,Pedidos!$E$2:$E$501,G$15) -> 419790 | H21: =SUM(B21:G21) -> 2020920
A22: TOTAL | B22: =SUM(B16:B21) -> 1051830 | C22: =SUM(C16:C21) -> 3464010 | D22: =SUM(D16:D21) -> 2499000 | E22: =SUM(E16:E21) -> 1471080 | F22: =SUM(F16:F21) -> 1273020 | G22: =SUM(G16:G21) -> 2298850 | H22: =SUM(H16:H21) -> 12057790

Sheet Pedidos
A1: pedido_id | B1: creado_en | C1: cliente_id | D1: sku | E1: categoria | F1: cantidad | G1: total_clp | H1: region | I1: estado_pedido
A2: PED-0001 | B2: 46250.504 | C2: CLI-0001 | D2: OFI-505 | E2: OFI | F2: 3 | G2: 38970 | H2: Coquimbo | I2: CONFIRMADO
A3: PED-0002 | B3: 46250.633 | C3: CLI-0002 | D3: ACC-606 | E3: ACC | F3: 1 | G3: 8990 | H3: Maule | I3: CONFIRMADO
A4: PED-0003 | B4: 46250.762 | C4: CLI-0003 | D4: ACC-606 | E4: ACC | F4: 1 | G4: 8990 | H4: Los Lagos | I4: CONFIRMADO
A5: PED-0004 | B5: 46250.892 | C5: CLI-0004 | D5: TEC-101 | E5: TEC | F5: 1 | G5: 19990 | H5: Los Lagos | I5: CONFIRMADO
A6: PED-0005 | B6: 46251.021 | C6: CLI-0005 | D6: ACC-606 | E6: ACC | F6: 1 | G6: 8990 | H6: Los Lagos | I6: CONFIRMADO
A7: PED-0006 | B7: 46251.15 | C7: CLI-0006 | D7: ACC-606 | E7: ACC | F7: 1 | G7: 8990 | H7: Coquimbo | I7: CONFIRMADO
A8: PED-0007 | B8: 46251.279 | C8: CLI-0007 | D8: TEC-101 | E8: TEC | F8: 1 | G8: 19990 | H8: Maule | I8: CONFIRMADO
A9: PED-0008 | B9: 46251.408 | C9: CLI-0008 | D9: DEP-404 | E9: DEP | F9: 1 | G9: 34990 | H9: Maule | I9: CONFIRMADO
A10: PED-0009 | B10: 46251.537 | C10: CLI-0009 | D10: OFI-505 | E10: OFI | F10: 1 | G10: 12990 | H10: Biobío | I10: CONFIRMADO
A11: PED-0010 | B11: 46251.667 | C11: CLI-0010 | D11: ACC-606 | E11: ACC | F11: 1 | G11: 8990 | H11: Valparaíso | I11: CONFIRMADO
A12: PED-0011 | B12: 46251.796 | C12: CLI-0011 | D12: ACC-606 | E12: ACC | F12: 1 | G12: 8990 | H12: Coquimbo | I12: CONFIRMADO
A13: PED-0012 | B13: 46251.925 | C13: CLI-0012 | D13: TEC-101 | E13: TEC | F13: 1 | G13: 19990 | H13: Coquimbo | I13: CONFIRMADO
... A501: PED-0500 | B501: 46314.958 | C501: CLI-0500 | D501: ACC-606 | E501: ACC | F501: 1 | G501: 8990 | H501: Valparaíso | I501: CONFIRMADO

Sheet Pagos
A1: pago_id | B1: pedido_id | C1: fecha_pago | D1: estado_pago | E1: monto_pagado_clp | F1: medio_pago
A2: PAG-0001 | B2: PED-0001 | C2: 46250.508 | D2: APROBADO | E2: 38970 | F2: TRANSFERENCIA
A3: PAG-0002 | B3: PED-0002 | C3: 46250.672 | D3: APROBADO | E3: 8990 | F3: TARJETA
A4: PAG-0003 | B4: PED-0003 | C4: 46250.771 | D4: APROBADO | E4: 8990 | F4: TARJETA
A5: PAG-0004 | B5: PED-0004 | C5: 46250.918 | D5: APROBADO | E5: 19990 | F5: TARJETA
A6: PAG-0005 | B6: PED-0005 | C6: 46251.028 | D6: APROBADO | E6: 8990 | F6: WEBPAY
A7: PAG-0006 | B7: PED-0006 | C7: 46251.203 | D7: APROBADO | E7: 8990 | F7: TRANSFERENCIA
A8: PAG-0007 | B8: PED-0007 | C8: 46251.29 | D8: APROBADO | E8: 19990 | F8: TARJETA
A9: PAG-0008 | B9: PED-0008 | C9: 46251.449 | D9: APROBADO | E9: 34990 | F9: TARJETA
A10: PAG-0009 | B10: PED-0009 | C10: 46251.598 | D10: APROBADO | E10: 12990 | F10: WEBPAY
A11: PAG-0010 | B11: PED-0010 | C11: 46251.736 | D11: APROBADO | E11: 8990 | F11: WEBPAY
A12: PAG-0011 | B12: PED-0011 | C12: 46251.823 | D12: APROBADO | E12: 8990 | F12: TRANSFERENCIA
A13: PAG-0012 | B13: PED-0012 | C13: 46251.953 | D13: APROBADO | E13: 18000 | F13: WEBPAY
... A501: PAG-0500 | B501: PED-0500 | C501: 46314.992 | D501: APROBADO | E501: 8990 | F501: WEBPAY

Sheet Envios
A1: envio_id | B1: pedido_id | C1: fecha_compromiso | D1: fecha_entrega | E1: estado_envio | F1: transportista
A2: ENV-0001 | B2: PED-0001 | C2: 46256 | D2: 46256 | E2: ENTREGADO | F2: RUTA_SUR
A3: ENV-0002 | B3: PED-0002 | C3: 46254 | D3: 46252 | E3: ENTREGADO | F3: RUTA_NORTE
A4: ENV-0003 | B4: PED-0003 | C4: 46256 | D4: 46257 | E4: ENTREGADO | F4: RUTA_NORTE
A5: ENV-0004 | B5: PED-0004 | C5: 46254 | D5: 46254 | E5: ENTREGADO | F5: RUTA_NORTE
A6: ENV-0005 | B6: PED-0005 | C6: 46256 | D6: 46256 | E6: ENTREGADO | F6: RUTA_CENTRO
A7: ENV-0006 | B7: PED-0006 | C7: 46256 | D7: 46255 | E7: ENTREGADO | F7: RUTA_NORTE
A8: ENV-0007 | B8: PED-0007 | C8: 46258 | D8: 46258 | E8: ENTREGADO | F8: RUTA_SUR
A9: ENV-0008 | B9: PED-0008 | C9: 46254 | D9: 46254 | E9: ENTREGADO | F9: RUTA_CENTRO
A10: ENV-0009 | B10: PED-0009 | C10: 46258 | D10: 46256 | E10: ENTREGADO | F10: RUTA_NORTE
A11: ENV-0010 | B11: PED-0010 | C11: 46256 | D11: 46256 | E11: ENTREGADO | F11: RUTA_CENTRO
A12: ENV-0011 | B12: PED-0011 | C12: 46254 | D12: 46254 | E12: ENTREGADO | F12: RUTA_SUR
A13: ENV-0012 | B13: PED-0012 | C13: 46255 | D13: 46255 | E13: ENTREGADO | F13: RUTA_NORTE
... A20: ENV-0019 | B20: PED-0019 | C20: 46255 | D20: 46254 | E20: ENTREGADO | F20: RUTA_SUR
A21: ENV-0020 | B21: PED-0020 | C21: 46306 | E21: EN_TRANSITO | F21: RUTA_SUR
A22: ENV-0021 | B22: PED-0021 | C22: 46258 | D22: 46258 | E22: ENTREGADO | F22: RUTA_CENTRO
A23: ENV-0022 | B23: PED-0022 | C23: 46260 | E23: PENDIENTE | F23: RUTA_CENTRO
A24: ENV-0023 | B24: PED-0023 | C24: 46257 | D24: 46255 | E24: ENTREGADO | F24: RUTA_CENTRO
A25: ENV-0024 | B25: PED-0024 | C25: 46257 | D25: 46256 | E25: ENTREGADO | F25: RUTA_NORTE
A26: ENV-0025 | B26: PED-0025 | C26: 46258 | D26: 46259 | E26: ENTREGADO | F26: RUTA_CENTRO
A27: ENV-0026 | B27: PED-0026 | C27: 46259 | D27: 46259 | E27: ENTREGADO | F27: RUTA_NORTE
A28: ENV-0027 | B28: PED-0027 | C28: 46257 | D28: 46259 | E28: ENTREGADO | F28: RUTA_CENTRO
A29: ENV-0028 | B29: PED-0028 | C29: 46257 | D29: 46258 | E29: ENTREGADO | F29: RUTA_CENTRO
A30: ENV-0029 | B30: PED-0029 | C30: 46310 | E30: EN_TRANSITO | F30: RUTA_CENTRO
A31: ENV-0030 | B31: PED-0030 | C31: 46260 | D31: 46260 | E31: ENTREGADO | F31: RUTA_SUR
A32: ENV-0031 | B32: PED-0031 | C32: 46257 | E32: PENDIENTE | F32: RUTA_NORTE
A33: ENV-0032 | B33: PED-0032 | C33: 46261 | D33: 46260 | E33: ENTREGADO | F33: RUTA_NORTE
A34: ENV-0033 | B34: PED-0033 | C34: 46261 | D34: 46259 | E34: ENTREGADO | F34: RUTA_NORTE
A35: ENV-0034 | B35: PED-0034 | C35: 46259 | D35: 46258 | E35: ENTREGADO | F35: RUTA_SUR
A36: ENV-0035 | B36: PED-0035 | C36: 46261 | D36: 46260 | E36: ENTREGADO | F36: RUTA_NORTE
A37: ENV-0036 | B37: PED-0036 | C37: 46258 | D37: 46260 | E37: ENTREGADO | F37: RUTA_NORTE
A38: ENV-0037 | B38: PED-0037 | C38: 46260 | D38: 46261 | E38: ENTREGADO | F38: RUTA_NORTE
A39: ENV-0038 | B39: PED-0038 | C39: 46258 | D39: 46258 | E39: ENTREGADO | F39: RUTA_SUR
A40: ENV-0039 | B40: PED-0039 | C40: 46259 | D40: 46259 | E40: ENTREGADO | F40: RUTA_CENTRO
A41: ENV-0040 | B41: PED-0040 | C41: 46262 | D41: 46262 | E41: ENTREGADO | F41: RUTA_CENTRO
A42: ENV-0041 | B42: PED-0041 | C42: 46262 | D42: 46260 | E42: ENTREGADO | F42: RUTA_SUR
A43: ENV-0042 | B43: PED-0042 | C43: 46258 | D43: 46258 | E43: ENTREGADO | F43: RUTA_SUR
A44: ENV-0043 | B44: PED-0043 | C44: 46261 | D44: 46260 | E44: ENTREGADO | F44: RUTA_NORTE
... A46: ENV-0045 | B46: PED-0045 | C46: 46262 | D46: 46262 | E46: ENTREGADO | F46: RUTA_SUR
A47: ENV-0046 | B47: PED-0046 | C47: 46306 | E47: EN_TRANSITO | F47: RUTA_SUR
...

Sheet Tickets
A1: ticket_id | B1: pedido_id | C1: creado_en | D1: prioridad | E1: sla_horas | F1: primera_respuesta_en | G1: estado_ticket | H1: motivo
A2: TIC-0001 | B2: PED-0157 | C2: 46305.077 | D2: BAJA | E2: 24 | F2: 46305.577 | G2: RESPONDIDO | H2: CONSULTA_PAGO
A3: TIC-0002 | B3: PED-0081 | C3: 46305.154 | D3: BAJA | E3: 24 | F3: 46305.654 | G3: RESPONDIDO | H3: PRODUCTO
A4: TIC-0003 | B4: PED-0397 | C4: 46305.231 | D4: MEDIA | E4: 12 | F4: 46305.481 | G4: RESPONDIDO | H4: CONSULTA_PAGO
A5: TIC-0004 | B5: PED-0427 | C5: 46305.308 | D5: BAJA | E5: 24 | F5: 46305.808 | G5: RESPONDIDO | H5: PRODUCTO
A6: TIC-0005 | B6: PED-0198 | C6: 46305.385 | D6: MEDIA | E6: 12 | F6: 46305.635 | G6: RESPONDIDO | H6: CONSULTA_PAGO
A7: TIC-0006 | B7: PED-0141 | C7: 46305.463 | D7: MEDIA | E7: 12 | F7: 46306.171 | G7: RESPONDIDO | H7: CONSULTA_PAGO
A8: TIC-0007 | B8: PED-0101 | C8: 46305.54 | D8: MEDIA | E8: 12 | G8: ABIERTO | H8: CONSULTA_PAGO
A9: TIC-0008 | B9: PED-0453 | C9: 46305.617 | D9: ALTA | E9: 4 | F9: 46305.7 | G9: RESPONDIDO | H9: CONSULTA_ENVIO
A10: TIC-0009 | B10: PED-0244 | C10: 46305.694 | D10: BAJA | E10: 24 | F10: 46306.194 | G10: RESPONDIDO | H10: CAMBIO_DIRECCION
A11: TIC-0010 | B11: PED-0134 | C11: 46305.771 | D11: ALTA | E11: 4 | F11: 46305.854 | G11: RESPONDIDO | H11: PRODUCTO
A12: TIC-0011 | B12: PED-0177 | C12: 46305.848 | D12: BAJA | E12: 24 | G12: ABIERTO | H12: CAMBIO_DIRECCION
A13: TIC-0012 | B13: PED-0007 | C13: 46305.925 | D13: MEDIA | E13: 12 | F13: 46306.633 | G13: RESPONDIDO | H13: CONSULTA_PAGO
A14: TIC-0013 | B14: PED-0337 | C14: 46306.002 | D14: BAJA | E14: 24 | F14: 46306.502 | G14: RESPONDIDO | H14: CAMBIO_DIRECCION
A15: TIC-0014 | B15: PED-0106 | C15: 46306.079 | D15: MEDIA | E15: 12 | G15: ABIERTO | H15: CAMBIO_DIRECCION
A16: TIC-0015 | B16: PED-0358 | C16: 46306.156 | D16: MEDIA | E16: 12 | F16: 46306.406 | G16: RESPONDIDO | H16: CAMBIO_DIRECCION
A17: TIC-0016 | B17: PED-0427 | C17: 46306.233 | D17: BAJA | E17: 24 | F17: 46306.733 | G17: RESPONDIDO | H17: CONSULTA_PAGO
A18: TIC-0017 | B18: PED-0300 | C18: 46306.31 | D18: MEDIA | E18: 12 | F18: 46306.56 | G18: RESPONDIDO | H18: CONSULTA_PAGO
A19: TIC-0018 | B19: PED-0381 | C19: 46306.387 | D19: BAJA | E19: 24 | F19: 46307.596 | G19: RESPONDIDO | H19: PRODUCTO
A20: TIC-0019 | B20: PED-0499 | C20: 46306.465 | D20: ALTA | E20: 4 | F20: 46306.548 | G20: RESPONDIDO | H20: PRODUCTO
A21: TIC-0020 | B21: PED-0110 | C21: 46306.542 | D21: ALTA | E21: 4 | F21: 46306.625 | G21: RESPONDIDO | H21: CONSULTA_ENVIO
A22: TIC-0021 | B22: PED-0327 | C22: 46306.619 | D22: MEDIA | E22: 12 | G22: ABIERTO | H22: CAMBIO_DIRECCION
A23: TIC-0022 | B23: PED-0191 | C23: 46306.696 | D23: MEDIA | E23: 12 | G23: ABIERTO | H23: CONSULTA_ENVIO
A24: TIC-0023 | B24: PED-0072 | C24: 46306.773 | D24: MEDIA | E24: 12 | F24: 46307.023 | G24: RESPONDIDO | H24: CONSULTA_ENVIO
A25: TIC-0024 | B25: PED-0207 | C25: 46306.85 | D25: MEDIA | E25: 12 | F25: 46307.558 | G25: RESPONDIDO | H25: CONSULTA_PAGO
A26: TIC-0025 | B26: PED-0451 | C26: 46306.927 | D26: ALTA | E26: 4 | F26: 46307.01 | G26: RESPONDIDO | H26: PRODUCTO
A27: TIC-0026 | B27: PED-0386 | C27: 46307.004 | D27: MEDIA | E27: 12 | F27: 46307.254 | G27: RESPONDIDO | H27: CAMBIO_DIRECCION
A28: TIC-0027 | B28: PED-0022 | C28: 46307.081 | D28: MEDIA | E28: 12 | F28: 46307.331 | G28: RESPONDIDO | H28: PRODUCTO
A29: TIC-0028 | B29: PED-0488 | C29: 46307.158 | D29: MEDIA | E29: 12 | G29: ABIERTO | H29: CAMBIO_DIRECCION
A30: TIC-0029 | B30: PED-0256 | C30: 46307.235 | D30: BAJA | E30: 24 | F30: 46307.735 | G30: RESPONDIDO | H30: CAMBIO_DIRECCION
A31: TIC-0030 | B31: PED-0005 | C31: 46307.312 | D31: MEDIA | E31: 12 | F31: 46308.021 | G31: RESPONDIDO | H31: CONSULTA_PAGO
A32: TIC-0031 | B32: PED-0319 | C32: 46307.39 | D32: ALTA | E32: 4 | F32: 46307.473 | G32: RESPONDIDO | H32: CONSULTA_ENVIO
A33: TIC-0032 | B33: PED-0437 | C33: 46307.467 | D33: ALTA | E33: 4 | F33: 46307.55 | G33: RESPONDIDO | H33: CONSULTA_PAGO
A34: TIC-0033 | B34: PED-0385 | C34: 46307.544 | D34: MEDIA | E34: 12 | G34: ABIERTO | H34: CONSULTA_ENVIO
A35: TIC-0034 | B35: PED-0304 | C35: 46307.621 | D35: BAJA | E35: 24 | F35: 46308.121 | G35: RESPONDIDO | H35: CAMBIO_DIRECCION
A36: TIC-0035 | B36: PED-0466 | C36: 46307.698 | D36: BAJA | E36: 24 | G36: ABIERTO | H36: CAMBIO_DIRECCION
A37: TIC-0036 | B37: PED-0174 | C37: 46307.775 | D37: ALTA | E37: 4 | F37: 46308.15 | G37: RESPONDIDO | H37: CAMBIO_DIRECCION
A38: TIC-0037 | B38: PED-0297 | C38: 46307.852 | D38: BAJA | E38: 24 | F38: 46308.352 | G38: RESPONDIDO | H38: CONSULTA_ENVIO
A39: TIC-0038 | B39: PED-0112 | C39: 46307.929 | D39: ALTA | E39: 4 | F39: 46308.012 | G39: RESPONDIDO | H39: CAMBIO_DIRECCION
A40: TIC-0039 | B40: PED-0179 | C40: 46308.006 | D40: BAJA | E40: 24 | F40: 46308.506 | G40: RESPONDIDO | H40: PRODUCTO
...

Sheet Incidencias
A1: incidencia_id | B1: tipo | C1: referencia | D1: pedido_id | E1: severidad | F1: detalle | G1: estado | H1: responsable | I1: ultima_accion
A2: ENVIO_ATRASADO:ENV-0020 | B2: ENVIO_ATRASADO | C2: ENV-0020 | D2: PED-0020 | E2: ALTA | F2: Compromiso 2026-10-11; 10 día(s) de atraso; estado EN_TRANSITO | G2: ABIERTO
A3: ENVIO_ATRASADO:ENV-0022 | B3: ENVIO_ATRASADO | C3: ENV-0022 | D3: PED-0022 | E3: ALTA | F3: Compromiso 2026-08-26; 56 día(s) de atraso; estado PENDIENTE | G3: ABIERTO
A4: ENVIO_ATRASADO:ENV-0029 | B4: ENVIO_ATRASADO | C4: ENV-0029 | D4: PED-0029 | E4: ALTA | F4: Compromiso 2026-10-15; 6 día(s) de atraso; estado EN_TRANSITO | G4: ABIERTO
A5: ENVIO_ATRASADO:ENV-0031 | B5: ENVIO_ATRASADO | C5: ENV-0031 | D5: PED-0031 | E5: ALTA | F5: Compromiso 2026-08-23; 59 día(s) de atraso; estado PENDIENTE | G5: ABIERTO
A6: ENVIO_ATRASADO:ENV-0046 | B6: ENVIO_ATRASADO | C6: ENV-0046 | D6: PED-0046 | E6: ALTA | F6: Compromiso 2026-10-11; 10 día(s) de atraso; estado EN_TRANSITO | G6: ABIERTO
A7: ENVIO_ATRASADO:ENV-0055 | B7: ENVIO_ATRASADO | C7: ENV-0055 | D7: PED-0055 | E7: MEDIA | F7: Compromiso 2026-10-20; 1 día(s) de atraso; estado EN_TRANSITO | G7: ABIERTO
A8: ENVIO_ATRASADO:ENV-0066 | B8: ENVIO_ATRASADO | C8: ENV-0066 | D8: PED-0066 | E8: ALTA | F8: Compromiso 2026-10-16; 5 día(s) de atraso; estado EN_TRANSITO | G8: ABIERTO
A9: ENVIO_ATRASADO:ENV-0067 | B9: ENVIO_ATRASADO | C9: ENV-0067 | D9: PED-0067 | E9: ALTA | F9: Compromiso 2026-08-31; 51 día(s) de atraso; estado PENDIENTE | G9: ABIERTO
A10: ENVIO_ATRASADO:ENV-0084 | B10: ENVIO_ATRASADO | C10: ENV-0084 | D10: PED-0084 | E10: ALTA | F10: Compromiso 2026-10-16; 5 día(s) de atraso; estado EN_TRANSITO | G10: ABIERTO
A11: ENVIO_ATRASADO:ENV-0091 | B11: ENVIO_ATRASADO | C11: ENV-0091 | D11: PED-0091 | E11: ALTA | F11: Compromiso 2026-10-11; 10 día(s) de atraso; estado EN_TRANSITO | G11: ABIERTO
A12: ENVIO_ATRASADO:ENV-0109 | B12: ENVIO_ATRASADO | C12: ENV-0109 | D12: PED-0109 | E12: ALTA | F12: Compromiso 2026-09-02; 49 día(s) de atraso; estado PENDIENTE | G12: ABIERTO
A13: ENVIO_ATRASADO:ENV-0112 | B13: ENVIO_ATRASADO | C13: ENV-0112 | D13: PED-0112 | E13: MEDIA | F13: Compromiso 2026-10-17; 4 día(s) de atraso; estado EN_TRANSITO | G13: ABIERTO
... A126: SLA_INCUMPLIDO:TIC-0120 | B126: SLA_INCUMPLIDO | C126: TIC-0120 | D126: PED-0055 | E126: MEDIA | F126: SLA 12 h; apertura 2026-10-19 06:00; primera respuesta 2026-10-19 23:00 | G126: ABIERTO

Sheet Parametros
A1: PARÁMETROS Y CRITERIOS
A4: Parámetro | B4: Valor
A5: Fecha de corte | B5: 2026-10-21
A6: Ventana duplicado (minutos) | B6: 10
A7: Tickets SLA ALTA (h) | B7: 4
A8: Tickets SLA MEDIA (h) | B8: 12
A9: Tickets SLA BAJA (h) | B9: 24
A10: Moneda | B10: CLP
A11: Naturaleza de los datos | B11: FICTICIOS / DEMOSTRACIÓN
A13: Los informes son generados por Python. La planilla es una foto fija, sin sincronización automática.

Sheet Guia
A1: GUÍA DE LECTURA
A4: Sección | B4: Qué contiene
A5: Panel | B5: Métricas operativas, distribución y gráficos
A6: Resumen_cruzado | B6: Matriz regional por categoría; cálculos actualizables por fórmulas
A7: Pedidos / Pagos / Envios / Tickets | B7: Registros sintéticos para búsqueda e investigación
A8: Incidencias | B8: Hallazgos detectados al corte de la simulación
A9: Fecha de corte | B9: 2026-10-21 (ver Parametros)
A10: Actualizar informes | B10: Ejecutar: python scripts/analizar.py --as-of 2026-10-21
A11: Actualizar la planilla | B11: Reimportar reports/incidencias.csv tras cada análisis
A12: Tabla dinámica nativa | B12: En Google Sheets: seleccionar Pedidos!A1:I501 → Insertar → Tabla dinámica
